Workbook

Sheet January 2020
A1: FORMAT LIST OF ACTUAL BENEFICIARIES
C2: January 2020
J3: Total No. Of Beneficiaries: 287
J4: Male: | K4: 255
J5: Female: | K5: 32
A6: a. Individuals | J6: Others:(S.C./PWD): 38
F7: Types of Goods/Services Received | J7: DATE OF IMPLEMENTATION
A8: NAME OF BENEFICIARIES | C8: GENDER | D8: BARANGAY | E8: MUNICIPALITY | F8: Contact No./Email | H8: QUANTITY | I8: COST('000)
F9: Address(if any) | G9: Type/Species | H9: RECEIVED | J9: TYPE | K9: SATISFIED/
H10: (Unit/kg/pcs.) | K10: NOT SATISFIED | O10: As of January 1-7, 2020
A11: DATE | O11: TILAPIA
A12: 2 | B12: Benjamin Nuez | C12: Male | D12: Cabigupan | E12: Trinidad | G12: Excel | H12: 3500 | I12: 700 | J12: pond | K12: satisfied | M12: 800 | O12: Sold | P12: 356300
A13: 2 | B13: Sherwin Balaba | C13: Male | D13: Pob. Sur | E13: Carmen | G13: Excel | H13: 4000 | I13: 800 | J13: pond | K13: satisfied | M13: 600 | O13: Dispersed | P13: 31500
A14: 2 | B14: Alie Esid | C14: Female | D14: Burgos | E14: Talibon | G14: Excel | H14: 500 | I14: 100 | J14: pond | K14: satisfied | M14: 50 | P14: =SUM(P12:P13) -> 387800
A15: 2 | B15: Reymond Omaña | C15: Male | D15: Buacao | E15: Clarin | G15: Excel | H15: 1500 | I15: 300 | J15: pond | K15: satisfied | M15: =H15/5 -> 300
A16: 2 | B16: Joselito Carnice | C16: Male | D16: Los Angeles | E16: Ubay | G16: Excel | H16: 2500 | I16: 500 | J16: pond | K16: satisfied | M16: =H16/5 -> 500 | O16: KOI
A17: 2 | B17: Virginia Descallar | C17: Female | D17: San Carlos | E17: Pilar | G17: Excel | H17: 1500 | I17: 300 | J17: pond | K17: satisfied | M17: =H17/5 -> 300 | O17: Sold | P17: 234
A18: 2 | B18: Magdalino Pandac | C18: Male | D18: Aloja | E18: Batuan | G18: Excel | H18: 3000 | I18: 600 | J18: pond | K18: satisfied | M18: 300
A19: 2 | B19: Alexander Doloso Jr. | C19: Male | D19: San Isidro | E19: Talibon | G19: Excel | H19: 40000 | I19: 8000 | J19: pond | K19: satisfied | M19: 50000 | O19: ULANG
A20: 2 | B20: Teny Peliño | C20: Male | D20: San Antonio | E20: Duero | G20: Excel | H20: 4000 | I20: 800 | J20: pond | K20: satisfied | M20: 600 | O20: Sold | P20: 1100
A21: 2 | B21: Teny Peliño | C21: Male | D21: San Antonio | E21: Duero | G21: KoiCarp | H21: 10 | I21: 100 | J21: pond | K21: satisfied
A22: 2 | B22: Francisco Bautista | C22: Male | D22: M. Roxas | E22: Trinidad | G22: Excel | H22: 3000 | I22: 600 | J22: pond | K22: satisfied | M22: 600
A23: 2 | B23: Elmer Teimpo | C23: Male | D23: Villafuerte | E23: Carmen | G23: Excel | H23: 2500 | I23: 500 | J23: pond | K23: satisfied | M23: 300
A24: 2 | B24: Brian Cuyacot | C24: Male | D24: Bugang | E24: San Miguel | G24: Excel | H24: 11000 | I24: 2200 | J24: pond | K24: satisfied | M24: 2200
A25: 2 | B25: Ariel Adaya | C25: Male | D25: La Salvacion | E25: Carmen | G25: Excel | H25: 500 | I25: 100 | J25: pond | K25: satisfied | M25: 150 | O25: =SUM(H12:H20,H22:H31,H40,H42:H43,H45,H47:H48,H50,H52:H53,H55,H58:H60,H62:H63,H65,H67,H70:H75,H77:H80,H83,H87,H89,H92:H94,H96:H100,H102:H103,H108:H109,H111:H119,H121,H123:H127,H129:H134,H137:H146,H150:H160,H162,H164:H165,H167:H168,H171,H173:H176,H178:H181,H183:H192,H194:H197,H199:H200,H203:H209,H212,H214:H219,H221:H222,H224:H226,H229:H230,H232:H237,H239,H241:H243,H245:H246,H248,H250:H257,H259:H261,H263:H265,H268,H270:H273,H275:H284,H286:H287,H290:H291,H293:H297,H299:H303,H305,H307,H309:H312,H314:H315,H317:H318,H323:H324,H326,H328:H331,H333:H336,H338:H357,H359:H360,H362:H364) -> 788150
A26: 2 | B26: Emmanuel Lupian | C26: Male | D26: Lawis | E26: Inabanga | G26: Excel | H26: 2000 | I26: 400 | J26: pond | K26: satisfied | M26: =H26/5 -> 400
A27: 2 | B27: Danilo Olaguer | C27: Male | D27: Balaga | E27: Mabini | G27: Excel | H27: 12000 | I27: 2400 | J27: pond | K27: satisfied | M27: 600
A28: 2 | B28: Vicente Malabute | C28: Male | D28: Malitbog | E28: Dagohoy | G28: Excel | H28: 3400 | I28: 680 | J28: pond | K28: satisfied | M28: 1000
A29: 2 | B29: Gerie Gepalago | C29: Male | D29: Pobalcion | E29: San Isidro | G29: Excel | H29: 400 | I29: 80 | J29: pond | K29: satisfied | M29: 80
A30: 2 | B30: Ronald Manal | C30: Male | D30: Sur | E30: Sagbayan | G30: Excel | H30: 500 | I30: 100 | J30: pond | K30: satisfied | M30: 300
A31: 2 | B31: Eric Basay | C31: Male | D31: Pobalcion | E31: Catigbian | G31: Excel | H31: 3000 | I31: 600 | J31: pond | K31: satisfied | M31: 600
A32: 2 | B32: Nestor Calamba | C32: Male | D32: Sta. Cruz | E32: Sierra Bullones | G32: Excel | H32: 500 | I32: dispersed | J32: pond | K32: satisfied | M32: 110
A33: 2 | B33: Nestor Calamba | C33: Male | D33: Sta. Cruz | E33: Sierra Bullones | G33: KoiCarp | H33: 10 | I33: 100 | J33: pond | K33: satisfied
A34: 2 | B34: Tonron dela Peña | C34: Male | D34: Sta. Cruz | E34: Sierra Bullones | G34: Excel | H34: 500 | I34: dispersed | J34: pond | K34: satisfied | M34: 100
A35: 2 | B35: Helario Malubay | C35: Male | D35: Villa Garcia | E35: Sierra Bullones | G35: Excel | H35: 500 | I35: dispersed | J35: pond | K35: satisfied | M35: 110
A36: 2 | B36: Helario Malubay | C36: Male | D36: Villa Garcia | E36: Sierra Bullones | G36: KoiCarp | H36: 5 | I36: 50 | J36: pond | K36: satisfied
A37: 2 | B37: Editha Pacot | C37: Female | D37: Villa Garcia | E37: Sierra Bullones | G37: Excel | H37: 500 | I37: dispersed | J37: pond | K37: satisfied | M37: 115
A38: 2 | B38: Editha Pacot | C38: Female | D38: Villa Garcia | E38: Sierra Bullones | G38: KoiCarp | H38: 5 | I38: 50 | J38: pond | K38: satisfied
A39: 2 | B39: Nestor Ramos | C39: Male | D39: Nahawan | E39: Clarin | G39: Excel | H39: 500 | I39: dispersed | J39: pond | K39: satisfied | M39: 400
A40: 2 | B40: Nestor Ramos | C40: Male | D40: Nahawan | E40: Clarin | G40: Excel | H40: 1500 | I40: 300 | J40: pond | K40: satisfied
...

Sheet January (Group)
A1: FORMAT LIST OF ACTUAL BENEFICIARIES
C2: January 2020
K3: Total No. Of Beneficiaries: 6
K4: Male: | L4: 3
K5: Female: | L5: 3
A6: a. Groups | K6: Others:(S.C./PWD)
C7: NUMBER | F7: Contact | G7: Name of | H7: Types of Goods/Services Received | K7: DATE OF IMPLEMENTATION
A8: NAME OF LGU/ASSOCIATION | C8: OF | D8: BARANGAY | E8: MUNICIPALITY | F8: No./Email | G8: Representatives | I8: QUANTITY | J8: COST('000)
C9: MEMBERS | F9: Address (if | G9: who received | H9: Type/Species | I9: RECEIVED | K9: TYPE | L9: SATISFIED/
F10: any) | I10: (Unit/kg/pcs. | L10: NOT SATISFIED
A11: DATE
A12: 2 | B12: LGU Tubigon | E12: Tubigon | G12: Victor Boligao | H12: Excel | I12: 5200 | J12: dispersed | K12: pond | L12: satisfied | N12: =I12/5 -> 1040 | O12: =I12+I13+I14+I15+I16 -> 28200
A13: 2 | B13: LGU Catigbian | E13: Catigbian | G13: Emma Merano | H13: Excel | I13: 6000 | J13: dispersed | K13: pond | L13: satisfied | N13: =I13/5 -> 1200
A14: 16 | B14: LGU Garcia Hernandez | E14: Garcia Hernandez | G14: Mary Ann Abucejo | H14: Excel | I14: 6000 | J14: dispersed | K14: pond | L14: satisfied | N14: =I14/5 -> 1200
A15: 16 | B15: LGU Alburquerque | E15: Alburquerque | G15: Cresente Bernaldes | H15: Excel | I15: 6000 | J15: dispersed | K15: pond | L15: satisfied | N15: 1200
A16: 20 | B16: Magsaysay Lower Farmers Association (MLFA) | D16: Magsaysay | E16: Talibon | G16: Angelito Oroyan | H16: Excel | I16: 5000 | J16: dispersed | K16: cage | L16: satisfied | N16: =5000/5 -> 1000
A17: 21 | B17: UBFF | H17: Excel Breeders | I17: 330 | J17: dispersed | N17: =SUM(N12:N16) -> 5640
I20: SUMMARY:
I21: Direct Client:
B22: Prepared and Submitted by: | E22: Noted by: | I22: Coordinating Office: | J22: 28,200 pcs.
I23: C. Carp: | J23: 0
I24: Ornamental Fish: | J24: 0
B25: GAYMELO Y. LOPEZ | E25: MARIO N. RUINATA, Ph. D. | I25: Catfish | J25: 0
B26: Aqua II/Center Chief | E26: Research, Development & Extension Coordinating Office | I26: Freshwater Prawn: | J26: 0
I27: Total area (sq.m)
I28: Freshwater: | J28: 4640
I29: Brackishwater: | J29: 1000

Sheet February 2020
A1: FORMAT LIST OF ACTUAL BENEFICIARIES
C2: February 2020
J3: Total No. Of Beneficiaries: 281
J4: Male: | K4: 232
J5: Female: | K5: 49
A6: a. Individuals | J6: Others:(S.C./PWD): 47
F7: Types of Goods/Services Received | J7: DATE OF IMPLEMENTATION
A8: NAME OF BENEFICIARIES | C8: GENDER | D8: BARANGAY | E8: MUNICIPALITY | F8: Contact No./Email | H8: QUANTITY | I8: COST('000)
F9: Address(if any) | G9: Type/Species | H9: RECEIVED | J9: TYPE | K9: SATISFIED/
H10: (Unit/kg/pcs.) | K10: NOT SATISFIED | Q10: February 3-5, 2020
A11: DATE
A12: 3 | B12: Salvador majomot | C12: Male | D12: Banlasan | E12: Tubigon | G12: Excel | H12: 1000 | I12: 200 | J12: pond | K12: satisfied | N12: 300 | Q12: TILAPIA
A13: 3 | B13: Anthony Cadenas | C13: Male | D13: Guadalupe | E13: Carmen | G13: Excel | H13: 500 | I13: dispersed | J13: pond | K13: satisfied | N13: 200 | Q13: Sold | S13: 326800 | T13: =SUM(H12,H14:H16,H18,H20,H22:H24,H26:H29,H31:H33,H31:H33,H37:H38,H40:H42,H44,H46:H48,H50:H51,H53:H56,H58,H60,H62,H64:H66,H70:H71,H73:H74,H76,H81:H82,H84:H85,H87:H88) -> 326800
A14: 3 | B14: Anthony Cadenas | C14: Male | D14: Guadalupe | E14: Carmen | G14: Excel | H14: 500 | I14: 100 | J14: pond | K14: satisfied | Q14: Dispersed | S14: 58200 | T14: =H13+H25+H30+H36+H45+H61+H67+H68+H69+H72 -> 8200 | U14: 50000 | V14: =SUM(T14:U14) -> 58200
A15: 3 | B15: Renie Jazo | C15: Male | D15: Bicao | E15: Carmen | G15: Excel | H15: 1000 | I15: 200 | J15: pond | K15: satisfied | N15: 400 | Q15: Total | S15: =SUM(S13:S14) -> 385000
A16: 3 | B16: Simplecio Balonga Jr | C16: Male | D16: Cabiguhan | E16: Trinidad | G16: Excel | H16: 21000 | I16: 4200 | J16: pond | K16: satisfied | N16: 3000 | Q16: ORNAMENTAL
A17: 3 | B17: Simplecio Balonga Jr | C17: Male | D17: Cabiguhan | E17: Trinidad | G17: Hito | H17: 50 | I17: 50 | J17: pond | K17: satisfied | Q17: Koi | S17: 415 | T17: =H34+H35+H57+H77 -> 415
A18: 3 | B18: Jessie Camanzo | C18: Male | D18: Poblacion | E18: Danao | G18: Excel | H18: 1000 | I18: 200 | J18: pond | K18: satisfied | N18: 336 | Q18: SwordTail | S18: 130 | T18: =H21+H78+H79 -> 130
A19: 3 | B19: Eduardo Saroje | C19: Male | D19: Guiang | E19: Guindulman | G19: Hito | H19: 500 | I19: 500 | J19: pond | K19: satisfied | Q19: Total | S19: =SUM(S17:S18) -> 545
A20: 3 | B20: Rogelio Sendo | C20: Male | D20: Poblacion | E20: Catigbian | G20: Excel | H20: 1000 | I20: 200 | J20: pond | K20: satisfied | N20: 300 | Q20: HITO
A21: 3 | B21: Moisel Bernales | C21: Male | D21: Guio-ang | E21: Guindulman | G21: Swordtail | H21: 30 | I21: 90 | J21: pond | K21: satisfied | Q21: Sold | S21: 1290 | T21: =H17+H19+H39+H43+H49+H52+H59+H63+H75+H83+H86 -> 1290
A22: 3 | B22: Johnny Jamil | C22: Male | D22: Cambacay | E22: Batuan | G22: Excel | H22: 700 | I22: 140 | J22: pond | K22: satisfied | N22: 150 | Q22: Dispersed | S22: 3000
A23: 3 | B23: Pedro Gumapac | C23: Male | D23: La Hacienda | E23: Alicia | G23: Excel | H23: 500 | I23: 100 | J23: pond | K23: satisfied | N23: =500/5 -> 100 | Q23: Total | S23: =SUM(S21:S22) -> 4290
A24: 3 | B24: Hermie Sunag | C24: Female | D24: Baunos | E24: San Isidro | G24: Excel | H24: 200 | I24: 40 | J24: pond | K24: satisfied | N24: 70
A25: 3 | B25: Saturnina Maputi | C25: Female | D25: Villa Teresita | E25: Ubay | G25: Excel | H25: 1200 | I25: dispersed | J25: pond | K25: satisfied | N25: 300
A26: 3 | B26: Jaime Barace | C26: Male | D26: Villafuerte | E26: Carmen | G26: Excel | H26: 4000 | I26: 800 | J26: pond | K26: satisfied | N26: 600
A27: 3 | B27: Jonel Saldom | C27: Male | D27: Bugang Sur | E27: Bilar | G27: Excel | H27: 6000 | I27: 1200 | J27: pond | K27: satisfied | N27: 1200
A28: 3 | B28: Lyneth Ybañez | C28: Female | D28: Aloja | E28: Batuan | G28: Excel | H28: 3000 | I28: 600 | J28: pond | K28: satisfied | N28: 500
A29: 3 | B29: Eldie Travero | C29: Male | D29: San Jose | E29: Getafe | G29: Excel | H29: 6000 | I29: 1200 | J29: pond | K29: satisfied | N29: 2500
A30: 3 | B30: Rosie Gamalo | C30: Male | D30: Inaghuban | E30: Pilar | G30: Excel | H30: 500 | I30: dispersed | J30: pond | K30: satisfied | N30: 400
A31: 3 | B31: Rosie Gamalo | C31: Male | D31: Inaghuban | E31: Pilar | G31: Excel | H31: 1500 | I31: 600 | J31: pond | K31: satisfied
A32: 3 | B32: Niemesio Tutor | C32: Male | D32: Poblacion | E32: Alicia | G32: Excel | H32: 6000 | I32: 1200 | J32: pond | K32: satisfied | N32: 1000
A33: 3 | B33: Cherry Ann Gualde | C33: Female | D33: La Libertad | E33: Carmen | G33: Excel | H33: 500 | I33: 100 | J33: pond | K33: satisfied
A34: 3 | B34: Cherry Ann Gualde | C34: Female | D34: La Libertad | E34: Carmen | G34: Koicarp | H34: 6 | I34: 90 | J34: pond | K34: satisfied
A35: 3 | B35: Cherry Ann Gualde | C35: Female | D35: La Libertad | E35: Carmen | G35: Koicarp | H35: 4 | I35: 80 | J35: pond | K35: satisfied
A36: 3 | B36: Manuel Decasa | C36: Male | D36: Bicao | E36: Carmen | G36: Excel | H36: 500 | I36: dispersed | J36: pond | K36: satisfied | N36: 225
A37: 3 | B37: Manuel Decasa | C37: Male | D37: Bicao | E37: Carmen | G37: Excel | H37: 500 | I37: 100 | J37: pond | K37: satisfied
A38: 3 | B38: Joel Torculas | C38: Male | D38: Poblacion | E38: Batuan | G38: Excel | H38: 100 | I38: 20 | J38: pond | K38: satisfied
A39: 3 | B39: Joel Torculas | C39: Male | D39: Poblacion | E39: Batuan | G39: Hito | H39: 30 | I39: 30 | J39: pond | K39: satisfied
A40: 3 | B40: Arthur Hinampas | C40: Male | D40: Poblacion | E40: Alicia | G40: Excel | H40: 10000 | I40: 2000 | J40: pond | K40: satisfied | N40: 2000
...

Sheet February (Group)
A1: FORMAT LIST OF ACTUAL BENEFICIARIES
C2: February, 2020
K3: Total No. Of Beneficiaries: 9
K4: Male: | L4: 6
K5: Female: | L5: 3
A6: a. Groups | K6: Others:(S.C./PWD)
C7: NUMBER | F7: Contact | G7: Name of | H7: Types of Goods/Services Received | K7: DATE OF IMPLEMENTATION
A8: NAME OF LGU/ASSOCIATION | C8: OF | D8: BARANGAY | E8: MUNICIPALITY | F8: No./Email | G8: Representatives | I8: QUANTITY | J8: COST('000)
C9: MEMBERS | F9: Address (if | G9: who received | H9: Type/Species | I9: RECEIVED | K9: TYPE | L9: SATISFIED/
F10: any) | I10: (Unit/kg/pcs. | L10: NOT SATISFIED
A11: DATE
A12: 3 | B12: LGU Antequera | E12: Antequera | G12: Paterna Premagado | H12: Excel | I12: 15500 | J12: dispersed | K12: pond | L12: satisfied | N12: =I12/5 -> 3100 | O12: =I12+I14+I15+I16 -> 50000
A13: 3 | B13: PFO Cebu | E13: Cebu | G13: Edgardo Delfin | H13: Hito | I13: 3000 | J13: dispersed | K13: pond | L13: satisfied
A14: 4 | B14: Panghagban Tilapia Grower Assoc. | D14: Panghagban | E14: Buenavista | G14: Samuel Lucero | H14: Excel | I14: 7500 | J14: dispersed | K14: pond | L14: satisfied | N14: =I14/5 -> 1500 | O14: =I12+I14+I15+I16+I17+I18+I19+I21 -> 158000
A15: 4 | B15: LGU Tubigon | E15: Tubigon | G15: Victor Boligao | H15: Excel | I15: 7000 | J15: dispersed | K15: pond | L15: satisfied | N15: =I15/5 -> 1400
A16: 4 | B16: LGU Catigbian | E16: Catigbian | G16: Emma Merano | H16: Excel | I16: 20000 | J16: dispersed | K16: pond | L16: satisfied | N16: =I16/5 -> 4000
A17: 12 | B17: Kasama sa Reporma Los Angeles Community for Integrated Livelihood Assoc. | D17: Los Angeles | E17: Ubay | G17: Josefina Tacmoy | H17: Excel | I17: 30000 | J17: dispersed | K17: pond | L17: satisfied | N17: =I17/5 -> 6000
A18: 13 | B18: Sto. Niño Farmers Assoc. | D18: Villahermoso | E18: Carmen | G18: Emilio Agbon | H18: Excel | I18: 5000 | J18: dispersed | K18: pond | L18: satisfied | N18: =I18/5 -> 1000 | O18: 35000
A19: 18 | B19: City Agriculture Office - Guihulngan City | E19: Guihulngan City, Negros Oriental | G19: Joel Cadiz | H19: Excel | I19: 61000 | J19: dispersed | K19: pond | L19: satisfied | N19: =I19/5 -> 12200
A20: 18 | B20: City Agriculture Office - Guihulngan City | E20: Guihulngan City, Negros Oriental | G20: Joel Cadiz | H20: Koicarp | I20: 30 | J20: dispersed | K20: pond | L20: satisfied
A21: 19 | B21: LGU - San Isidro | E21: San Isidro | G21: Ruel Cabug-os | H21: Excel | I21: 12000 | J21: 2400 | K21: pond | L21: satisfied | N21: =I21/5 -> 2400
J23: SUMMARY: | N23: =SUM(N12:N22) -> 31600
J24: Direct Client: 12,000 pcs
B25: Prepared and Submitted by: | E25: Noted by: | J25: Coordinating Office: 146,000 pcs
J26: C. Carp: 0
J27: Ornamental Fish: 30 pcs
B28: GAYMELO Y. LOPEZ | E28: MARIO N. RUINATA, Ph. D. | J28: Catfish: 3,000 pcs
B29: AQUA II/OIC- Center Chief | E29: Research, Development & Extension Coordinating Office | J29: Freshwater Prawn: 0
J30: Total area (sq.m)
J31: Freshwater: 31,600 sq. m.
J32: Brackishwater:

Sheet March 2020
A1: FORMAT LIST OF ACTUAL BENEFICIARIES
C2: March 2020
J3: Total No. Of Beneficiaries:
J4: Male:
J5: Female:
A6: a. Individuals | J6: Others:(S.C./PWD)
F7: Types of Goods/Services Received | J7: DATE OF IMPLEMENTATION
A8: NAME OF BENEFICIARIES | C8: GENDER | D8: BARANGAY | E8: MUNICIPALITY | F8: Contact No./Email | H8: QUANTITY | I8: COST('000)
F9: Address(if any) | G9: Type/Species | H9: RECEIVED | J9: TYPE | K9: SATISFIED/
H10: (Unit/kg/pcs.) | K10: NOT SATISFIED
A11: DATE
A12: 2 | B12: Nilo Niones | C12: Male | D12: Calatrava | E12: Carmen | G12: Excel | H12: 1000 | I12: 200 | J12: pond | K12: satisfied
A13: 2 | B13: Bonifacio Aranas | C13: Male | D13: Lajog | E13: Clarin | G13: Excel | H13: 250 | I13: 100 | J13: pond | K13: satisfied | M13: 15
A14: 2 | B14: Ponciano Viador | C14: Male | D14: Datag | E14: Inabanga | G14: Excel | H14: 150 | I14: 45 | J14: pond | K14: satisfied | M14: 40
A15: 2 | B15: Ramon Gulayan | C15: Male | D15: Buacao | E15: Clarin | G15: Excel | H15: 1200 | I15: 480 | J15: pond | K15: satisfied | M15: 200
A16: 2 | B16: Pepe gamalo | C16: Male | D16: Inaghubaw | E16: Pilar | G16: Excel | H16: 4000 | I16: 800 | J16: pond | K16: satisfied | M16: 1200
A17: 2 | B17: Florencio Lague | C17: Male | D17: Katipunan | E17: Carmen | G17: Excel | H17: 500 | I17: 100 | J17: pond | K17: satisfied | M17: 9
A18: 2 | B18: Gil Cadenas | C18: Male | D18: Guadalupe | E18: Carmen | G18: Excel | H18: 500 | I18: dispersed | J18: pond | K18: satisfied
A19: 2 | B19: Gil Cadenas | C19: Male | D19: Guadalupe | E19: Carmen | G19: Excel | H19: 2500 | I19: 500 | J19: pond | K19: satisfied
A20: 2 | B20: Mario Andot | C20: Male | D20: Campagao | E20: Bilar | G20: Excel | H20: 2000 | I20: 400 | J20: pond | K20: satisfied | M20: 300
A21: 2 | B21: Aries Dela Torre | C21: Male | D21: Libertad | E21: Tubigon | G21: Excel | H21: 1500 | I21: 300 | J21: pond | K21: satisfied | M21: 900
A22: 2 | B22: Crisel Bulan | C22: Female | D22: Dampas | E22: Tagbilaran | G22: Koicarp | H22: 33 | I22: 165 | J22: pond | K22: satisfied
A23: 2 | B23: Alan Lucero | C23: Male | E23: Batuan | G23: Excel | H23: 2000 | I23: 400 | J23: pond | K23: satisfied | M23: 1800
A24: 2 | B24: Felicitas Deliman | C24: Female | D24: Quezon | E24: Batuan | G24: Excel | H24: 4000 | I24: 800 | J24: pond | K24: satisfied
A25: 2 | B25: Ebenezer Abergas | C25: Male | D25: Ilihan | E25: Inabanga | G25: Excel | H25: 300 | I25: 60 | J25: pond | K25: satisfied
A26: 2 | B26: Pablo Lozada Jr. | C26: Male | D26: Cansaguit | E26: Loon | G26: Excel | H26: 150 | I26: 30 | J26: pond | K26: satisfied
A27: 2 | B27: Gabriel Espejo | C27: Male | D27: Poblacion Sur | E27: Carmen | G27: Excel | H27: 3500 | I27: 700 | J27: pond | K27: satisfied | M27: 450
A28: 2 | B28: Gabriel Espejo | C28: Male | D28: Poblacion Sur | E28: Carmen | G28: Koicarp | H28: 40 | I28: 400 | J28: pond | K28: satisfied
A29: 2 | B29: Rogelio Ombajin | C29: Male | D29: Buacao | E29: Clarin | G29: Excel | H29: 3000 | I29: 1200 | J29: pond | K29: satisfied | M29: 500
A30: 2 | B30: Aram Gacera | C30: Male | D30: Sto. Rosario | E30: Inabanga | G30: Excel | H30: 200 | I30: 40 | J30: pond | K30: satisfied | M30: 60
A31: 2 | B31: Petra Pesanos | C31: Female | D31: Buacao | E31: Clarin | G31: Excel | H31: 800 | I31: 160 | J31: pond | K31: satisfied | M31: 150
A32: 2 | B32: James Torregosa | C32: Male | D32: Magtangtang | E32: Danao | G32: Excel | H32: 4000 | I32: 800 | J32: pond | K32: satisfied | M32: 1500
A33: 2 | B33: Edgardo Podador | C33: Male | D33: Bunacan | E33: Tubigon | G33: Excel | H33: 1300 | I33: 260 | J33: pond | K33: satisfied | M33: 300
A34: 2 | B34: Jimmy Olarita | C34: Male | D34: San Miguel | E34: Dagohoy | G34: Excel | H34: 600 | I34: 120 | J34: pond | K34: satisfied | M34: 100
A35: 2 | B35: Marino Montojo | C35: Male | D35: Caluwasan | E35: Clarin | G35: Excel | H35: 36000 | I35: 7200 | J35: pond | K35: satisfied | M35: 15000
A36: 2 | B36: Arlene Cabusao | C36: Female | D36: Poblacion Sur | E36: Carmen | G36: Excel | H36: 1000 | I36: 400 | J36: pond | K36: satisfied | M36: 600
A37: 2 | B37: Arlene Cabusao | C37: Female | D37: Poblacion Sur | E37: Carmen | G37: Koicarp | H37: 20 | I37: 200 | J37: pond | K37: satisfied
A38: 2 | B38: Marvie Basmayor | C38: Female | D38: Mayana | E38: Jagna | G38: Swordtail | H38: 150 | I38: 450 | J38: pond | K38: satisfied
A39: 2 | B39: Almer Dungol | C39: Male | D39: Kinan-owan | E39: Trinidad | G39: Excel | H39: 6000 | I39: 1200 | J39: pond | K39: satisfied | M39: 1200
A40: 2 | B40: Glenn Divinagracia | C40: Male | D40: Sta. Fe | E40: Danao | G40: Excel | H40: 1000 | I40: 200 | J40: pond | K40: satisfied | M40: 100
...

Sheet March (Group)
A1: FORMAT LIST OF ACTUAL BENEFICIARIES
C2: March, 2020
K3: Total No. Of Beneficiaries:
K4: Male:
K5: Female:
A6: a. Groups | K6: Others:(S.C./PWD)
C7: NUMBER | F7: Contact | G7: Name of | H7: Types of Goods/Services Received | K7: DATE OF IMPLEMENTATION
A8: NAME OF LGU/ASSOCIATION | C8: OF | D8: BARANGAY | E8: MUNICIPALITY | F8: No./Email | G8: Representatives | I8: QUANTITY | J8: COST('000)
C9: MEMBERS | F9: Address (if | G9: who received | H9: Type/Species | I9: RECEIVED | K9: TYPE | L9: SATISFIED/
F10: any) | I10: (Unit/kg/pcs. | L10: NOT SATISFIED
A11: DATE
A12: 2 | B12: LGU Valencia | D12: Canmanico | E12: Valencia | G12: Jerajane Namindang | H12: Excel | I12: 5000 | J12: dispersed | K12: pond | L12: satisfied | N12: =I12+I14+I15 -> 19000
A13: 3 | B13: LGU Antiquera | D13: Tupas | E13: Antiquera | G13: Bertillo Tongco | H13: C. carp | I13: 61 | J13: dispersed
A14: 4 | B14: LGU Maribojoc | E14: Maribojoc | G14: Faith Angelie Inot | H14: Excel | I14: 4000 | J14: dispersed
A15: 4 | B15: LGU Mabini | E15: Mabini | G15: Marcelino Taghap | H15: Excel | I15: 10000 | J15: dispersed
A16: 13 | B16: LGU Tubigon | E16: Tubigon | G16: Victor Boligao | H16: Excel | I16: 6000 | J16: dispersed
A17: 24 | B17: LGU San Isidro | E17: San Isidro | G17: Ruel Cabug-os | H17: Excel | I17: 4000 | J17: dispersed
A18: 31 | B18: LGU Pilar | D18: Malinaw Dam | E18: Pilar | G18: Carmen Cubrado | H18: Excel | I18: 229000 | J18: dispersed
J22: SUMMARY:
J23: Direct Client:
B24: Prepared and Submitted by: | E24: Noted by: | J24: Coordinating Office:
J25: C. Carp:
J26: Ornamental Fish:
B27: GAYMELO Y. LOPEZ | E27: MARIO N. RUINATA, Ph. D. | J27: Catfish:
B28: AQUA II/OIC- Center Chief | E28: Assistant Under The Office Of The Regional Director | J28: Freshwater Prawn:
J29: Total area (sq.m)
J30: Freshwater:
J31: Brackishwater:

Sheet April 2020
A1: FORMAT LIST OF ACTUAL BENEFICIARIES
C2: April 2020
J3: Total No. Of Beneficiaries:
J4: Male:
J5: Female:
A6: a. Individuals | J6: Others:(S.C./PWD)
F7: Types of Goods/Services Received | J7: DATE OF IMPLEMENTATION
A8: NAME OF BENEFICIARIES | C8: GENDER | D8: BARANGAY | E8: MUNICIPALITY | F8: Contact No./Email | H8: QUANTITY | I8: COST('000)
F9: Address(if any) | G9: Type/Species | H9: RECEIVED | J9: TYPE | K9: SATISFIED/
H10: (Unit/kg/pcs.) | K10: NOT SATISFIED
A11: DATE
A12: 1 | B12: Ruel Cabug-os | C12: Male | D12: Abehilan | E12: San Isidro | G12: Excel | H12: 2500 | I12: 500 | J12: pond | K12: satisfied | M12: 500
A13: 1 | B13: Eduardo Navaro | C13: Male | D13: San Antonio | E13: Sagbayan | G13: Excel | H13: 3500 | I13: 700 | J13: pond | K13: satisfied | M13: 400
A14: 2 | B14: Terry Cook | C14: Male | D14: Macaas | E14: Tubigon | G14: Excel | H14: 200 | I14: 60 | J14: pond | K14: satisfied
A15: 2 | B15: Juliser Mangmang | C15: Male | D15: Nueva Fuerza | E15: Carmen | G15: Excel | H15: 500 | I15: dispersed | J15: pond | K15: satisfied | M15: 900
A16: 2 | B16: Juliser Mangmang | C16: Male | D16: Nueva Fuerza | E16: Carmen | G16: Excel | H16: 1500 | I16: 300 | J16: pond | K16: satisfied
A17: 3 | B17: Nelson Suralta | C17: Male | D17: Pob. Sur | E17: Clarin | G17: Excel | H17: 500 | I17: dispersed | J17: pond | K17: satisfied | M17: 150
A18: 3 | B18: Nelson Suralta | C18: Male | D18: Pob. Sur | E18: Clarin | G18: Excel | H18: 2000 | I18: 400 | J18: pond | K18: satisfied
A19: 3 | B19: Ritchie Botoy | C19: Male | D19: Buangan | E19: Clarin | G19: Excel | H19: 500 | I19: 100 | J19: pond | K19: satisfied
A20: 3 | B20: Pedro Valentus | C20: Male | D20: Villafuerte | E20: Carmen | G20: Excel | H20: 4000 | I20: 1200 | J20: pond | K20: satisfied | M20: 5400
A21: 4 | B21: Cris Doria | C21: Male | D21: Zamora | E21: Bilar | G21: Excel | H21: 2000 | I21: 400 | J21: pond | K21: satisfied
A22: 4 | B22: Efren Lumenario | C22: Male | D22: Villafuerte | E22: Carmen | G22: Excel | H22: 23000 | I22: 9200 | J22: pond | K22: satisfied
A23: 4 | B23: Arnel Sanchez | C23: Male | D23: Inaghuban | E23: Pilar | G23: Excel | H23: 2000 | I23: 600 | J23: pond | K23: satisfied | M23: 72
A24: 5 | B24: Jacinto Torreon | C24: Male | D24: Banahaw | E24: Inabanga | G24: Excel | H24: 300 | I24: 90 | J24: pond | K24: satisfied
A25: 5 | B25: Reynaldo Omamalin | C25: Male | D25: Montesuerte | E25: Carmen | G25: Excel | H25: 1000 | I25: 200 | J25: pond | K25: satisfied | M25: 200
A26: 5 | B26: Aloysius Siarot | C26: Male | D26: Nahawan | E26: Clarin | G26: Excel | H26: 500 | I26: 100 | J26: pond | K26: satisfied | M26: 100
A27: 5 | B27: Francisco Fernandez | C27: Male | D27: Bongbong | E27: Catigbian | G27: Excel | H27: 300 | I27: 60 | J27: pond | K27: satisfied | M27: 50
A28: 6 | B28: Reymond Omaña | C28: Male | D28: Buacao | E28: Clarin | G28: Excel | H28: 500 | I28: dispersed | J28: pond | K28: satisfied
A29: 6 | B29: Reymond Omaña | C29: Male | D29: Buacao | E29: Clarin | G29: Excel | H29: 2000 | I29: 400 | J29: pond | K29: satisfied
A30: 6 | B30: Reynaldo Espina | C30: Male | D30: Tan-awan | E30: Tubigon | G30: Excel | H30: 500 | I30: dispersed | J30: pond | K30: satisfied
A31: 6 | B31: Reynaldo Espina | C31: Male | D31: Tan-awan | E31: Tubigon | G31: Excel | H31: 2000 | I31: 400 | J31: pond | K31: satisfied
A32: 6 | B32: Terso Cerencio Sr. | C32: Male | D32: San Miguel | E32: Dagohoy | G32: Excel | H32: 500 | I32: dispersed | J32: pond | K32: satisfied | O32: April 1-8, 2020
A33: 6 | B33: Terso Cerencio Sr. | C33: Male | D33: San Miguel | E33: Dagohoy | G33: Excel | H33: 3000 | I33: 600 | J33: pond | K33: satisfied | O33: TILAPIA
A34: 6 | B34: Marcelino Ecat | C34: Male | D34: San Miguel | E34: Dagohoy | G34: Excel | H34: 500 | I34: dispersed | J34: pond | K34: satisfied | O34: Sold | P34: 56600
A35: 6 | B35: Marcelino Ecat | C35: Male | D35: San Miguel | E35: Dagohoy | G35: Excel | H35: 3500 | I35: 700 | J35: pond | K35: satisfied | O35: Dispersed | P35: 3000
A36: 7 | B36: Dann Vaño | C36: Male | D36: Bogtongbod | E36: Clarin | G36: Excel | H36: 100 | I36: 20 | J36: pond | K36: satisfied | O36: Total | P36: 59600
A37: 7 | B37: Joena Parohinog | C37: Female | D37: Nahawan | E37: Clarin | G37: Excel | H37: 200 | I37: 40 | J37: pond | K37: satisfied | M37: 25
A38: 8 | B38: Nemesio Oronan | C38: Male | D38: Tubod | E38: Clarin | G38: Excel | H38: 2500 | I38: 1000 | J38: pond | K38: satisfied | M38: 1000
A39: 8 | B39: Geoffrey Cepedoza | C39: Male | D39: Magtangtang | E39: Danao | G39: Excel | H39: 5000 | I39: 1500 | J39: pond | K39: satisfied
A40: 8 | B40: Ma. Rodela | C40: Female | D40: San Ramon | E40: Sagbayan | G40: Excel | H40: 500 | I40: dispersed | J40: pond | K40: satisfied | M40: 800
...

Sheet April (Group)
A1: FORMAT LIST OF ACTUAL BENEFICIARIES
C2: April, 2020
K3: Total No. Of Beneficiaries:
K4: Male:
K5: Female:
A6: a. Groups | K6: Others:(S.C./PWD)
C7: NUMBER | F7: Contact | G7: Name of | H7: Types of Goods/Services Received | K7: DATE OF IMPLEMENTATION
A8: NAME OF LGU/ASSOCIATION | C8: OF | D8: BARANGAY | E8: MUNICIPALITY | F8: No./Email | G8: Representatives | I8: QUANTITY | J8: COST('000)
C9: MEMBERS | F9: Address (if | G9: who received | H9: Type/Species | I9: RECEIVED | K9: TYPE | L9: SATISFIED/
F10: any) | I10: (Unit/kg/pcs. | L10: NOT SATISFIED
A11: DATE
A12: 21 | B12: LGU Loboc | E12: Loboc | G12: Jelen Nalugon | H12: Excel | I12: 62000 | J12: dispersed | K12: river | L12: satisfied | N12: =I12+I13 -> 92000
A13: 24 | B13: LGU Garcia Hernandez | D13: Lungsodaan | E13: Garcia Hernandez | G13: Mary Ann Abucejo | H13: Excel | I13: 30000 | J13: dispersed | L13: satisfied
A14: 28 | B14: LGU San Isidro | E14: San Isidro | G14: Romeo Torralba | H14: Excel | I14: 6000 | J14: 1200 | K14: pond | L14: satisfied | M14: =6000/5 -> 1200
A15: 28 | B15: KADIWA on WHEELS | E15: Cortes | H15: Marketable Tilapia | I15: 31.5 | J15: 2520
J22: SUMMARY:
J23: Direct Client:
B24: Prepared and Submitted by: | E24: Noted by: | J24: Coordinating Office:
J25: C. Carp:
J26: Ornamental Fish:
B27: GAYMELO Y. LOPEZ | E27: MARIO N. RUINATA, Ph. D. | J27: Catfish:
B28: AQUA II/OIC- Center Chief | E28: Assistant Under The Office Of The Regional Director | J28: Freshwater Prawn:
J29: Total area (sq.m)
J30: Freshwater:
J31: Brackishwater:

Sheet May 2020
A1: FORMAT LIST OF ACTUAL BENEFICIARIES
C2: May 2020
J3: Total No. Of Beneficiaries:
J4: Male:
J5: Female:
A6: a. Individuals | J6: Others:(S.C./PWD)
F7: Types of Goods/Services Received | J7: DATE OF IMPLEMENTATION
A8: NAME OF BENEFICIARIES | C8: GENDER | D8: BARANGAY | E8: MUNICIPALITY | F8: Contact No./Email | H8: QUANTITY | I8: COST('000)
F9: Address(if any) | G9: Type/Species | H9: RECEIVED | J9: TYPE | K9: SATISFIED/
H10: (Unit/kg/pcs.) | K10: NOT SATISFIED
A11: DATE
A12: 4 | B12: Rey Indiana | C12: Male | D12: Buenos Aires | E12: Tubigon | G12: Excel | H12: 3000 | I12: 600 | J12: pond | K12: satisfied | M12: 600
A13: 4 | B13: Glenn Estrosas | C13: Male | D13: Bunacan | E13: Tubigon | G13: Excel | H13: 300 | I13: 60 | J13: pond | K13: satisfied | M13: 60
A14: 4 | B14: Daryl Añabieza | C14: Male | D14: Liloan Norte | E14: Inabanga | G14: Koi Carp | H14: 10 | I14: 100 | J14: pond | K14: satisfied
A15: 4 | B15: Jam Alfie Lagrimas | C15: Male | D15: Tinibgan | E15: Calape | G15: Excel | H15: 200 | I15: 40 | J15: pond | K15: satisfied | M15: 40
A16: 4 | B16: Jam Alfie Lagrimas | C16: Male | D16: Tinibgan | E16: Calape | G16: Koi Carp | H16: 5 | I16: 50 | J16: pond | K16: satisfied
A17: 4 | B17: Mark Pihongo | C17: Male | D17: Ilijan Sur | E17: Tubigon | G17: Excel | H17: 250 | I17: 50 | J17: pond | K17: satisfied | M17: 50
A18: 4 | B18: Elden Betalmos | C18: Male | D18: Riverside | E18: Inabanga | G18: Excel | H18: 500 | I18: 100 | J18: pond | K18: satisfied | M18: 100
A19: 4 | B19: Nonie Milagrosa | C19: Male | D19: Alegria | E19: Carmen | G19: Excel | H19: 300 | I19: 60 | J19: pond | K19: satisfied | M19: 50
A20: 4 | B20: Gregory Paul Batausa | C20: Male | D20: Cabulijan | E20: Tubigon | G20: Excel | H20: 250 | I20: 50 | J20: pond | K20: satisfied | M20: 50
A21: 4 | B21: Aga Niño Franco | C21: Male | D21: Cantuyok | E21: Clarin | G21: Koi Carp | H21: 10 | I21: 100 | J21: pond | K21: satisfied
A22: 4 | B22: John Mark Tapales | C22: Male | D22: Nahawan | E22: Clarin | G22: Excel | H22: 750 | I22: 150 | J22: pond | K22: satisfied | M22: 150
A23: 4 | B23: Avito Cano | C23: Male | D23: Pinayagan | E23: Tubigon | G23: Koi Carp | H23: 10 | I23: 100 | J23: pond | K23: satisfied
A24: 4 | B24: Junil Tronoyba | C24: Male | D24: Nahawan | E24: Clarin | G24: Excel | H24: 1000 | I24: 200 | J24: pond | K24: satisfied | M24: 200
A25: 4 | B25: Ailyn Lapoja | C25: Female | D25: Canmaya | E25: Sagbayan | G25: Excel | H25: 400 | I25: dispersed | J25: pond | K25: satisfied | M25: 150
A26: 4 | B26: Jun Buaya | C26: Male | D26: Pob. Sur | E26: Carmen | G26: Excel | H26: 6000 | I26: 1200 | J26: pond | K26: satisfied | M26: 1200
A27: 4 | B27: Mario Maglajos | C27: Male | D27: Poblacion | E27: Catigbian | G27: Excel | H27: 300 | I27: 60 | J27: pond | K27: satisfied | M27: 60
A28: 4 | B28: Ma. Cristina Casia | C28: Female | E28: Carmen | G28: Koi Carp | H28: 175 | I28: 875 | J28: pond | K28: satisfied
A29: 4 | B29: Dominador Camencia | C29: Male | D29: Villarcayo | E29: Carmen | G29: Excel | H29: 500 | I29: dispersed | J29: pond | K29: satisfied | M29: 100
A30: 4 | B30: Dominador Camencia | C30: Male | D30: Villarcayo | E30: Carmen | G30: Excel | H30: 1500 | I30: 300 | J30: pond | K30: satisfied
A31: 4 | B31: Dominador Camencia | C31: Male | D31: Villarcayo | E31: Carmen | G31: Koi Carp | H31: 70 | I31: 350 | J31: pond | K31: satisfied
A32: 4 | B32: Loloy Espinal | C32: Male | D32: La Libertad | E32: Carmen | G32: Excel | H32: 1000 | I32: 200 | J32: pond | K32: satisfied | M32: 200
A33: 4 | B33: Bernabe De Guzman | C33: Female | D33: Del Carmen | E33: Balilihan | G33: Excel | H33: 2000 | I33: 400 | J33: pond | K33: satisfied | M33: 1600
A34: 4 | B34: Daniel Degamo | C34: Male | D34: Tontonan | E34: Clarin | G34: Excel | H34: 1500 | I34: 300 | J34: pond | K34: satisfied | M34: 300
A35: 4 | B35: Roy Balaba | C35: Male | D35: Can Oling | E35: Dagohoy | G35: Excel | H35: 250 | I35: 50 | J35: pond | K35: satisfied | M35: 150
A36: 4 | B36: Martin Comamao | C36: Male | D36: Ubujan | E36: Sagbayan | G36: Excel | H36: 3000 | I36: 600 | J36: pond | K36: satisfied | M36: 600
A37: 4 | B37: Pedro Itallo | C37: Male | D37: Bunacan | E37: Tubigon | G37: Excel | H37: 2300 | I37: 460 | J37: pond | K37: satisfied | M37: 300
A38: 4 | B38: Felipe Petalco | C38: Male | D38: Banahao | E38: Inabanga | G38: Excel | H38: 500 | I38: dispersed | J38: pond | K38: satisfied | M38: 100
A39: 4 | B39: Lucio Ones | C39: Male | D39: Bactol | E39: Balilihan | G39: Excel | H39: 1000 | I39: 200 | J39: pond | K39: satisfied | M39: 300
A40: 4 | B40: Ariel Lagare | C40: Male | D40: Omjon | E40: Valencia | G40: Excel | H40: 2500 | I40: 500 | J40: pond | K40: satisfied | M40: 300
...

Sheet May (Group)
A1: FORMAT LIST OF ACTUAL BENEFICIARIES
C2: May, 2020
K3: Total No. Of Beneficiaries:
K4: Male:
K5: Female:
A6: a. Groups | K6: Others:(S.C./PWD)
C7: NUMBER | F7: Contact | G7: Name of | H7: Types of Goods/Services Received | K7: DATE OF IMPLEMENTATION
A8: NAME OF LGU/ASSOCIATION | C8: OF | D8: BARANGAY | E8: MUNICIPALITY | F8: No./Email | G8: Representatives | I8: QUANTITY | J8: COST('000)
C9: MEMBERS | F9: Address (if | G9: who received | H9: Type/Species | I9: RECEIVED | K9: TYPE | L9: SATISFIED/
F10: any) | I10: (Unit/kg/pcs. | L10: NOT SATISFIED
A11: DATE
A12: 7 | B12: Manga National High School | D12: Manga | E12: Tagbilaran | G12: Pablita Cabarles | H12: Excel | I12: 260 | J12: dispersed | K12: pond | L12: satisfied | M12: 12
A13: 7 | B13: LGU Tubigon | E13: Tubigon | G13: Victor Boligao | H13: Excel | I13: 6500 | J13: dispersed | M13: =6500/5 -> 1300
A14: 18 | B14: LGU Buenavista | E14: Buenavista | G14: Lino Divinagracia | H14: Excel | I14: 3000 | J14: dispersed | K14: pond | L14: satisfied | M14: =3000/5 -> 600
A15: 18 | B15: LGU Buenavista | E15: Buenavista | G15: Lino Divinagracia | H15: Koicarp | I15: 9 | J15: dispersed
A16: 28 | B16: LGU Bilar | D16: Dagohoy | E16: Bilar | G16: Rosendo Bantugan | H16: Common carp | I16: 4000 | J16: dispersed | K16: river | L16: satisfied
A17: 28 | B17: LGU Sevilla | D17: Ewon | E17: Sevilla | G17: Crispin Lumantas | H17: Common carp | I17: 10000 | J17: dispersed | K17: lake | L17: satisfied
J22: SUMMARY:
J23: Direct Client:
B24: Prepared and Submitted by: | E24: Noted by: | J24: Coordinating Office:
J25: C. Carp:
J26: Ornamental Fish:
B27: GAYMELO Y. LOPEZ | E27: MARIO N. RUINATA, Ph. D. | J27: Catfish:
B28: AQUA II/OIC- Center Chief | E28: Research, Development & Extension Coordinating Office | J28: Freshwater Prawn:
J29: Total area (sq.m)
J30: Freshwater:
J31: Brackishwater:

Sheet June 2020
A1: FORMAT LIST OF ACTUAL BENEFICIARIES
C2: June 2020
J3: Total No. Of Beneficiaries:
J4: Male:
J5: Female:
A6: a. Individuals | J6: Others:(S.C./PWD)
F7: Types of Goods/Services Received | J7: DATE OF IMPLEMENTATION
A8: NAME OF BENEFICIARIES | C8: GENDER | D8: BARANGAY | E8: MUNICIPALITY | F8: Contact No./Email | H8: QUANTITY | I8: COST('000)
F9: Address(if any) | G9: Type/Species | H9: RECEIVED | J9: TYPE | K9: SATISFIED/
H10: (Unit/kg/pcs.) | K10: NOT SATISFIED
A11: DATE
A12: 4 | B12: Mario Lozada | C12: Male | D12: San Miguel | E12: Dagohoy | G12: C. carp | H12: 500 | I12: 300 | J12: pond | K12: satisfied
A13: 4 | B13: Sherwin Balaba | C13: Male | D13: Poblacion | E13: Carmen | G13: C. carp | H13: 800 | I13: 480 | J13: pond | K13: satisfied
A14: 4 | B14: Domeciano Valentos | C14: Male | D14: Tambo-an | E14: Carmen | G14: Excel | H14: 1500 | I14: 300 | J14: pond | K14: satisfied | M14: 300
A15: 4 | B15: Manuel Valentos | C15: Male | D15: Tambo-an | E15: Carmen | G15: Excel | H15: 3000 | I15: 600 | J15: pond | K15: satisfied | M15: 600
A16: 4 | B16: Ramil Sumagaysay | C16: Male | D16: Cagawasan | E16: Inabanga | G16: Excel | H16: 1000 | I16: 200 | J16: pond | K16: satisfied | M16: 800
A17: 4 | B17: Ramil Sumagaysay | C17: Male | D17: Cagawasan | E17: Inabanga | G17: Excel | H17: 500 | I17: dispersal | J17: pond | K17: satisfied
A18: 4 | B18: Virginia Descallar | C18: Female | D18: San Carlos | E18: Pilar | G18: Excel | H18: 500 | I18: dispersal | J18: pond | K18: satisfied | M18: 900
A19: 4 | B19: Virginia Descallar | C19: Female | D19: San Carlos | E19: Pilar | G19: Excel | H19: 3500 | I19: 700 | J19: pond | K19: satisfied
A20: 4 | B20: Virginia Descallar | C20: Female | D20: San Carlos | E20: Pilar | G20: Ulang | H20: 150 | I20: 150 | J20: pond | K20: satisfied
A21: 4 | B21: Ariel Aplacador | C21: Male | D21: Ilijan Sur | E21: Tubigon | G21: Excel | H21: 1200 | I21: 240 | J21: pond | K21: satisfied | M21: 240
A22: 4 | B22: Jaime Regala | C22: Male | D22: Villaflor | E22: Carmen | G22: Excel | H22: 4000 | I22: 800 | J22: pond | K22: satisfied | M22: 800
A23: 4 | B23: Ramon Gulayan | C23: Male | D23: Buacao | E23: Clarin | G23: Excel | H23: 1000 | I23: 200 | J23: pond | K23: satisfied | M23: 300
A24: 4 | B24: Antonio Peracho | C24: Male | D24: San Vicente | E24: Pilar | G24: Excel | H24: 500 | I24: dispersal | J24: pond | K24: satisfied | M24: 266
A25: 4 | B25: Antonio Peracho | C25: Male | D25: San Vicente | E25: Pilar | G25: C. carp | H25: 200 | I25: 120 | J25: pond | K25: satisfied
A26: 4 | B26: Samuel Cabangbang | C26: Male | D26: Libertad | E26: Tubigon | G26: C. carp | H26: 200 | I26: 120 | J26: pond | K26: satisfied
A27: 4 | B27: Linly Sarmiento | C27: Male | D27: Buenos Aires | E27: Tubigon | G27: Excel | H27: 1000 | I27: 200 | J27: pond | K27: satisfied | M27: 200
A28: 4 | B28: Juanita Amparado | C28: Female | D28: Villaflor | E28: Clarin | G28: Excel | H28: 16000 | I28: 4800 | J28: pond | K28: satisfied | M28: 3500
A29: 4 | B29: Gelardo Jumandos | C29: Male | D29: Nueva Fuerza | E29: Carmen | G29: Excel | H29: 900 | I29: 180 | J29: pond | K29: satisfied | M29: 200
A30: 4 | B30: Ja-ker Baug-bog | C30: Male | D30: Montesuerte | E30: Carmen | G30: Excel | H30: 1000 | I30: 200 | J30: pond | K30: satisfied | M30: 300
A31: 4 | B31: Anthony Alimpolos | C31: Male | D31: Lapaz | E31: Carmen | G31: Excel | H31: 1000 | I31: 200 | J31: pond | K31: satisfied | M31: 300
A32: 5 | B32: Raulito Ucay | C32: Male | D32: Patrocinio | E32: Cortes | G32: Excel | H32: 500 | I32: 100 | J32: pond | K32: satisfied | M32: 50
A33: 5 | B33: Raulito Ucay | C33: Male | D33: Patrocinio | E33: Cortes | G33: C. carp | H33: 100 | I33: 60 | J33: pond | K33: satisfied
A34: 5 | B34: Roberto Cañete | C34: Male | D34: Dagnawan | E34: Inabanga | G34: Excel | H34: 500 | I34: 100 | J34: pond | K34: satisfied | M34: 100
A35: 5 | B35: Arnel Pasilan Jr. | C35: Male | D35: Dagnawan | E35: Inabanga | G35: Excel | H35: 1000 | I35: 200 | J35: pond | K35: satisfied | M35: 300
A36: 5 | B36: Jonathan Avelino | C36: Male | D36: San Carlos | E36: Danao | G36: Excel | H36: 1000 | I36: 200 | J36: pond | K36: satisfied | M36: 300
A37: 5 | B37: Jonathan Avelino | C37: Male | D37: San Carlos | E37: Danao | G37: C. carp | H37: 100 | I37: 60 | J37: pond | K37: satisfied
A38: 5 | B38: Jerry Cole | C38: Male | D38: Buenauerte | E38: Pilar | G38: Excel | H38: 1000 | I38: 200 | J38: pond | K38: satisfied | M38: 200
A39: 5 | B39: Luis Requirme | C39: Male | D39: Ilijan | E39: Inabanga | G39: Excel | H39: 700 | I39: 140 | J39: pond | K39: satisfied | M39: 200
A40: 5 | B40: Romeo Gandulfos | C40: Male | D40: Danahao | E40: Clarin | G40: Excel | H40: 600 | I40: 120 | J40: pond | K40: satisfied | M40: 100
...

Sheet June (Group)
A1: FORMAT LIST OF ACTUAL BENEFICIARIES
C2: June, 2020
K3: Total No. Of Beneficiaries:
K4: Male:
K5: Female:
A6: a. Groups | K6: Others:(S.C./PWD)
C7: NUMBER | F7: Contact | G7: Name of | H7: Types of Goods/Services Received | K7: DATE OF IMPLEMENTATION
A8: NAME OF LGU/ASSOCIATION | C8: OF | D8: BARANGAY | E8: MUNICIPALITY | F8: No./Email | G8: Representatives | I8: QUANTITY | J8: COST('000)
C9: MEMBERS | F9: Address (if | G9: who received | H9: Type/Species | I9: RECEIVED | K9: TYPE | L9: SATISFIED/
F10: any) | I10: (Unit/kg/pcs. | L10: NOT SATISFIED
A11: DATE
A12: 2 | B12: LGU Ubay | D12: Bongbong | E12: Ubay | G12: Andres Apa-ap | H12: C. carp | I12: 8000 | J12: dispersal | K12: dam | L12: satisfied
A13: 2 | B13: LGU Sierra Bullones | D13: Matin-ao | E13: Sierra Bullones | G13: Medardo Digal | H13: C. carp | I13: 3000 | J13: dispersal | K13: lake | L13: satisfied
A14: 2 | B14: LGU Bilar | D14: Poblacion | E14: Bilar | G14: Renerio Tejada | H14: C. carp | I14: 3500 | J14: dispersal | L14: satisfied
A15: 2 | B15: LGU Bilar | D15: Poblacion | E15: Bilar | H15: Excel | I15: 1000 | J15: dispersal | L15: satisfied
A16: 3 | B16: Sto. Niño Water Impounding & Irrigators Assoc. | D16: Sto. Niño | E16: Talibon | G16: Meneo Auxtero | H16: Excel | I16: 5000 | J16: dispersal | K16: fish cage | L16: satisfied | M16: 1000
A17: 3 | B17: LGU Talibon | D17: Zamora | E17: Talibon | G17: Retchel Escartin | H17: C. carp | I17: 10000 | J17: dispersal | K17: dam | L17: satisfied
A18: 3 | B18: LGU Talibon | D18: San Roque | E18: Talibon | G18: Angelito Oroyan | H18: C. carp | I18: 5000 | J18: dispersal | K18: dam | L18: satisfied
A19: 23 | B19: LGU Guindulman | E19: Guindulman | G19: Jaime Aranay | H19: Excel | I19: 1400 | J19: dispersal | L19: satisfied
A20: 23 | B20: LGU Guindulman | E20: Guindulman | H20: Excel Breeders | I20: 200 | J20: dispersal | L20: satisfied
A21: 23 | B21: LGU Carmen | D21: Poblacion | E21: Carmen | G21: Arlene Cabusao | H21: Excel | I21: 10500 | J21: dispersal | L21: satisfied
A22: 23 | B22: LGU Carmen | D22: Poblacion | E22: Carmen | H22: C. carp | I22: 465 | J22: dispersal | L22: satisfied
A23: 24 | B23: LGU Tubigon | E23: Tubigon | G23: Victor Boligao | H23: Excel | I23: 31700 | J23: dispersal | L23: satisfied | M23: 8000
A24: 26 | B24: LGU Cortes | E24: Cortes | G24: Ma. Luz Alcala | H24: Excel | I24: 8000 | J24: dispersal | L24: satisfied
J33: SUMMARY:
J34: Direct Client:
B35: Prepared and Submitted by: | E35: Noted by: | J35: Coordinating Office:
J36: C. Carp:
J37: Ornamental Fish:
B38: GAYMELO Y. LOPEZ | E38: MARIO N. RUINATA, Ph. D. | J38: Catfish:
B39: AQUA II/OIC- Center Chief | E39: Research, Development & Extension Coordinating Office | J39: Freshwater Prawn:
J40: Total area (sq.m)
J41: Freshwater:
J42: Brackishwater:

Sheet July (Group)
A1: FORMAT LIST OF ACTUAL BENEFICIARIES
C2: July, 2020
K3: Total No. Of Beneficiaries:
K4: Male:
K5: Female:
A6: a. Groups | K6: Others:(S.C./PWD)
C7: NUMBER | F7: Contact | G7: Name of | H7: Types of Goods/Services Received | K7: DATE OF IMPLEMENTATION
A8: NAME OF LGU/ASSOCIATION | C8: OF | D8: BARANGAY | E8: MUNICIPALITY | F8: No./Email | G8: Representatives | I8: QUANTITY | J8: COST('000)
C9: MEMBERS | F9: Address (if | G9: who received | H9: Type/Species | I9: RECEIVED | K9: TYPE | L9: SATISFIED/
F10: any) | I10: (Unit/kg/pcs. | L10: NOT SATISFIED
A11: DATE
A12: 15 | B12: LGU Sikatuna | E12: Sikatuna | G12: Ireneo Gabato | H12: Excel | I12: 18280 | J12: dispersal | L12: satisfied
A13: 15 | B13: PFO Bohol | E13: Tagbilaran | G13: Victor Doblas | H13: Excel | I13: 6500 | J13: dispersal | L13: satisfied
A14: 21 | B14: LGU Clarin | E14: Clarin | G14: Emmanuel Gulayan | H14: Hito | I14: 190 | J14: dispersal | L14: satisfied
J17: SUMMARY:
J18: Direct Client:
B19: Prepared and Submitted by: | E19: Noted by: | J19: Coordinating Office: 24,780 pcs.
J20: C. Carp:
J21: Ornamental Fish:
B22: GAYMELO Y. LOPEZ | E22: MARIO N. RUINATA, Ph. D. | J22: Catfish: | K22: 190 pcs.
B23: AQUA II/OIC- Center Chief | E23: Research, Development & Extension Coordinating Office | J23: Freshwater Prawn:
J24: Total area (sq.m)
J25: Freshwater:
J26: Brackishwater:

Sheet July 2020
A1: FORMAT LIST OF ACTUAL BENEFICIARIES
C2: July 2020
J3: Total No. Of Beneficiaries:
J4: Male:
J5: Female:
A6: a. Individuals | J6: Others:(S.C./PWD)
F7: Types of Goods/Services Received | J7: DATE OF IMPLEMENTATION
A8: NAME OF BENEFICIARIES | C8: GENDER | D8: BARANGAY | E8: MUNICIPALITY | F8: Contact No./Email | H8: QUANTITY | I8: COST('000)
F9: Address(if any) | G9: Type/Species | H9: RECEIVED | J9: TYPE | K9: SATISFIED/
H10: (Unit/kg/pcs.) | K10: NOT SATISFIED
A11: DATE
A12: 1 | B12: Francisco Bernaldez | C12: Male | D12: Sudlon | E12: Alicia | G12: Excel | H12: 12000 | I12: 2400 | J12: pond | K12: satisfied | M12: 2500
A13: 1 | B13: Joseph Inojales | C13: Male | D13: Tubod | E13: Candijay | G13: Excel | H13: 17000 | I13: 3400 | J13: pond | K13: satisfied | M13: 1000
A14: 1 | B14: Lenny Badiang | C14: Female | D14: Buenavista | E14: Carmen | G14: Excel | H14: 2000 | I14: 400 | J14: pond | K14: satisfied | M14: 400
A15: 1 | B15: Norman Hinautan | C15: Male | D15: Bunacan | E15: Tubigon | G15: Excel | H15: 1200 | I15: 240 | J15: pond | K15: satisfied | M15: 200
A16: 1 | B16: Cleo Tante | C16: Female | D16: Buenos Aires | E16: Tubigon | G16: Excel | H16: 2000 | I16: 400 | J16: pond | K16: satisfied | M16: 150
A17: 1 | B17: Belenda Bautista | C17: Female | D17: Sta. Fe | E17: Danao | G17: Excel | H17: 4000 | I17: 800 | J17: pond | K17: satisfied | M17: 900
A18: 1 | B18: Teodomero Suello | C18: Male | D18: Pobalcion | E18: Danao | G18: Excel | H18: 4000 | I18: 800 | J18: pond | K18: satisfied | M18: 900
A19: 1 | B19: Rey Omac | C19: Male | D19: Pamacsalan | E19: Pilar | G19: Excel | H19: 2000 | I19: 400 | J19: pond | K19: satisfied | M19: 200
A20: 1 | B20: Teodoro Quilag | C20: Male | D20: Ambuan | E20: Catigbian | G20: Excel | H20: 1000 | I20: 200 | J20: pond | K20: satisfied | M20: 300
A21: 1 | B21: Medardo Aparece | C21: Male | D21: Villaflor | E21: Clarin | G21: Excel | H21: 2500 | I21: 500 | J21: pond | K21: satisfied | M21: 500
A22: 1 | B22: Jorge Salo | C22: Male | D22: Candajec | E22: Clarin | G22: Excel | H22: 1000 | I22: 200 | J22: pond | K22: satisfied | M22: 200
A23: 1 | B23: Victor Adlaon | C23: Male | D23: Nueva Vida | E23: Carmen | G23: Excel | H23: 1500 | I23: 300 | J23: pond | K23: satisfied | M23: 250
A24: 1 | B24: Victor Magallane | C24: Male | D24: La Salvacion | E24: Carmen | G24: Excel | H24: 100 | I24: dispersal | J24: pond | K24: satisfied | M24: 10
A25: 1 | B25: Jonas Edtirgio | C25: Male | D25: Lusong | E25: Buenavista | G25: Excel | H25: 500 | I25: dispersal | J25: pond | K25: satisfied | M25: 300
A26: 1 | B26: Jonas Edtirgio | C26: Male | D26: Lusong | E26: Buenavista | G26: Excel | H26: 1000 | I26: 200 | J26: pond | K26: satisfied
A27: 1 | B27: Ronel Meliza | C27: Male | D27: Ma. Rosario | E27: Inabanga | G27: Excel | H27: 1000 | I27: 200 | J27: pond | K27: satisfied | M27: 300
A28: 1 | B28: Marivic Amang | C28: Female | D28: Cabacnitan | E28: Batuan | G28: Excel | H28: 12000 | I28: 2400 | J28: pond | K28: satisfied | M28: 1600
A29: 1 | B29: Simplicio Maputol | C29: Male | D29: San Agustin | E29: Sagbayan | G29: Excel | H29: 1600 | I29: 320 | J29: pond | K29: satisfied | M29: 300
A30: 1 | B30: Celvan Decenilla | C30: Male | D30: Villa Aurora | E30: Antequera | G30: Excel | H30: 2000 | I30: 400 | J30: pond | K30: satisfied | M30: 900
A31: 1 | B31: Jeremy Remoroza | C31: Male | D31: Matin-ao | E31: Carmen | G31: Excel | H31: 2000 | I31: 400 | J31: pond | K31: satisfied | M31: 400
A32: 1 | B32: Jeremy Remoroza | C32: Male | D32: Matin-ao | E32: Carmen | G32: Ulang | H32: 20 | I32: 20 | J32: pond | K32: satisfied
A33: 1 | B33: Zito Dañe | C33: Male | D33: Campagao | E33: Bilar | G33: Excel | H33: 1500 | I33: 300 | J33: pond | K33: satisfied | M33: 400
A34: 1 | B34: Joel Soson | C34: Male | D34: Garcia | E34: Batuan | G34: Excel | H34: 4000 | I34: 800 | J34: pond | K34: satisfied | M34: 1000
A35: 1 | B35: Joel Soson | C35: Male | D35: Garcia | E35: Batuan | G35: Ulang | H35: 20 | I35: 20 | J35: pond | K35: satisfied
A36: 1 | B36: Anecito Fernandez | C36: Male | D36: Rozas | E36: Trinidad | G36: Excel | H36: 5500 | I36: 1100 | J36: pond | K36: satisfied | M36: 1200
A37: 1 | B37: Fernando Perejan | C37: Male | D37: Nueva Montana | E37: Buenavista | G37: Excel | H37: 5000 | I37: 1000 | J37: pond | K37: satisfied | M37: 1000
A38: 1 | B38: Danilo Suello | C38: Male | D38: Poblacion | E38: Danao | G38: Excel | H38: 2000 | I38: 400 | J38: pond | K38: satisfied | M38: 600
A39: 1 | B39: Janin Lumagbas | C39: Male | D39: Matin-ao | E39: Carmen | G39: Excel | H39: 100 | I39: dispersal | J39: pond | K39: satisfied | M39: 10
A40: 2 | B40: Jevelyn Torrentira | C40: Female | D40: Calatrava | E40: Carmen | G40: Excel | H40: 500 | I40: 100 | J40: pond | K40: satisfied | M40: 150
...

Sheet August 2020
A1: FORMAT LIST OF ACTUAL BENEFICIARIES
C2: August 2020
J3: Total No. Of Beneficiaries:
J4: Male:
J5: Female:
A6: a. Individuals | J6: Others:(S.C./PWD)
F7: Types of Goods/Services Received | J7: DATE OF IMPLEMENTATION
A8: NAME OF BENEFICIARIES | C8: GENDER | D8: BARANGAY | E8: MUNICIPALITY | F8: Contact No./Email | H8: QUANTITY | I8: COST('000)
F9: Address(if any) | G9: Type/Species | H9: RECEIVED | J9: TYPE | K9: SATISFIED/
H10: (Unit/kg/pcs.) | K10: NOT SATISFIED
A11: DATE
A12: 4 | B12: Modesto Coquilla | C12: Male | D12: Alegria | E12: Catigbian | G12: Excel | H12: 1500 | I12: 300 | J12: pond | K12: satisfied | M12: 300
A13: 4 | B13: Nemesio Doria | C13: Male | D13: Villa Aurora | E13: Bilar | G13: Excel | H13: 18000 | I13: 3600 | J13: pond | K13: satisfied | M13: 4000
A14: 4 | B14: Ricardo Balag | C14: Male | D14: San Miguel | E14: Dagohoy | G14: Excel | H14: 500 | I14: dispersal | J14: pond | K14: satisfied | M14: 400
G15: Excel | H15: 2000 | I15: 400
A16: 4 | B16: Zoren Jay Puertos | C16: Male | D16: San Miguel | E16: Dagohoy | G16: Excel | H16: 500 | I16: dispersal | J16: pond | K16: satisfied | M16: 400
G17: Excel | H17: 1500 | I17: 300
A18: 4 | B18: Michelle Grace Lanoy | C18: Female | D18: San Miguel | E18: Dagohoy | G18: Excel | H18: 3000 | I18: 600 | J18: pond | K18: satisfied | M18: 1000
A19: 4 | B19: Camila Puertos | C19: Female | D19: San Miguel | E19: Dagohoy | G19: Excel | H19: 500 | I19: dispersal | J19: pond | K19: satisfied | M19: 500
G20: Excel | H20: 2000 | I20: 400
A21: 4 | B21: Lucila Timbal | C21: Female | D21: San Miguel | E21: Dagohoy | G21: Excel | H21: 500 | I21: dispersal | J21: pond | K21: satisfied | M21: 1500
G22: Excel | H22: 6000 | I22: 1200
A23: 4 | B23: Ronal Melicor | C23: Male | D23: Villarcayo | E23: Carmen | G23: Excel | H23: 3000 | I23: 600 | J23: pond | K23: satisfied | M23: 1296
A24: 4 | B24: Bonifacio Baro | C24: Male | D24: Hagbuaya | E24: Catigbian | G24: Excel | H24: 2000 | I24: 400 | J24: pond | K24: satisfied | M24: 300
A25: 4 | B25: Ambrosio Lomay | C25: Male | D25: Katipunan | E25: Carmen | G25: Excel | H25: 500 | I25: dispersal | J25: pond | K25: satisfied | M25: 225
A26: 4 | B26: Ambrosio Lomay | C26: Male | D26: Katipunan | E26: Carmen | G26: Excel | H26: 1500 | I26: 300
A27: 4 | B27: Prose Sucgang | C27: Male | D27: Magtangtang | E27: Danao | G27: Excel | H27: 500 | I27: 100 | J27: pond | K27: satisfied | M27: 100
A28: 4 | B28: Aric Leorna | C28: Male | D28: Villaflor | E28: Clarin | G28: Excel | H28: 1000 | I28: 200 | J28: pond | K28: satisfied | M28: 200
A29: 4 | B29: Gleceria Gaudicos | C29: Female | D29: Bongbong | E29: Catigbian | G29: Excel | H29: 200 | I29: 40 | J29: pond | K29: satisfied | M29: 40
A30: 4 | B30: Paolo Cajote | C30: Male | D30: Katipunan | E30: Carmen | G30: Excel | H30: 2000 | I30: 400 | J30: pond | K30: satisfied | M30: 600
A31: 4 | B31: Nestor Lingatong | C31: Male | D31: Canmano | E31: Sagbayan | G31: Excel | H31: 2000 | I31: 400 | J31: pond | K31: satisfied | M31: 300
A32: 4 | B32: Adel Aparece | C32: Male | D32: Villaflor | E32: Clarin | G32: Excel | H32: 1000 | I32: 200 | J32: pond | K32: satisfied | M32: 300
A33: 4 | B33: Arvin Tampos | C33: Male | D33: Panghagban | E33: Buenavista | G33: Excel | H33: 1000 | I33: 200 | J33: pond | K33: satisfied | M33: 50
A34: 4 | B34: Yurie Manayaga | C34: Male | D34: Pob. Norte | E34: Carmen | G34: Excel | H34: 2500 | I34: 500 | J34: pond | K34: satisfied | M34: 400
A35: 4 | B35: Beviano Basio | C35: Male | D35: Danahaw | E35: Clarin | G35: Excel | H35: 500 | I35: dispersal | J35: pond | K35: satisfied | M35: 525
A36: 4 | B36: Beviano Basio | C36: Male | D36: Danahaw | E36: Clarin | G36: Excel | H36: 2000 | I36: 400
A37: 4 | B37: Tito Unajan | C37: Male | D37: Pob. Sur | E37: Carmen | G37: Excel | H37: 8000 | I37: 1600 | J37: pond | K37: satisfied | M37: 1200
A38: 4 | B38: Efronio Sepe | C38: Male | D38: Buenos Aires | E38: Tubigon | G38: Excel | H38: 1200 | I38: 240 | J38: pond | K38: satisfied | M38: 250
A39: 4 | B39: Marcial Galler | C39: Male | D39: Cabagakian | E39: Dimiao | G39: Excel | H39: 2500 | I39: 500 | J39: pond | K39: satisfied | M39: 600
A40: 4 | B40: Juvy Cantaros | C40: Female | D40: Sta Cruz | E40: Batuan | G40: Excel | H40: 7000 | I40: 1400 | J40: pond | K40: satisfied | M40: 1500
...

Sheet August (Group)
A1: FORMAT LIST OF ACTUAL BENEFICIARIES
C2: August, 2020
K3: Total No. Of Beneficiaries:
K4: Male:
K5: Female:
A6: a. Groups | K6: Others:(S.C./PWD)
C7: NUMBER | F7: Contact | G7: Name of | H7: Types of Goods/Services Received | K7: DATE OF IMPLEMENTATION
A8: NAME OF LGU/ASSOCIATION | C8: OF | D8: BARANGAY | E8: MUNICIPALITY | F8: No./Email | G8: Representatives | I8: QUANTITY | J8: COST('000)
C9: MEMBERS | F9: Address (if | G9: who received | H9: Type/Species | I9: RECEIVED | K9: TYPE | L9: SATISFIED/
F10: any) | I10: (Unit/kg/pcs. | L10: NOT SATISFIED
A11: DATE
A12: 4 | B12: LGU - San Isidro | E12: San Isidro | H12: Excel | I12: 17000 | J12: 3400 | L12: satisfied
A13: 5 | B13: LGU - Clarin | E13: Clarin | G13: Emmanuel Gulayan | H13: Excel | I13: 3000 | J13: dispersal | L13: satisfied
A14: 5 | B14: Bagtic Masagana Multi-Purpose Coop. | D14: Poblacion | E14: Catigbian | G14: Mario Balio | H14: Excel | I14: 2000 | J14: 400 | L14: satisfied
A15: 7 | B15: LGU - Tubigon | E15: Tubigon | G15: Victor Boligao | H15: Excel | I15: 18759 | J15: dispersal | L15: satisfied
A16: 10 | B16: LGU - Jagna | D16: Pangdan | E16: Jagna | G16: Roderick Vertudazo | H16: Excel | I16: 22000 | J16: dispersal | L16: satisfied
A17: 11 | B17: PFO - Bohol | D17: Dao District | E17: Tagbilaran | G17: Victor Doblas | H17: Excel | I17: 8800 | J17: dispersal | L17: satisfied
A18: 11 | B18: PFO - Bohol | D18: Dao District | E18: Tagbilaran | H18: Hito | I18: 600 | J18: dispersal | L18: satisfied
A19: 18 | B19: LGU - San Isdiro | E19: San Isidro | G19: Ruel Cabug-os | H19: Excel | I19: 13700 | J19: 2740 | L19: satisfied | N19: 13700 | O19: sold
A20: 20 | B20: LGU - Antequera | D20: Tupas Lake | E20: Antequera | H20: C. carp | I20: 20000 | J20: dispersal | L20: satisfied
A21: 26 | B21: LGU - Clarin | E21: Clarin | G21: Emmanuel Gulayan | H21: Hito | I21: 500 | J21: dispersal | L21: satisfied
J29: SUMMARY:
J30: Direct Client:
B31: Prepared and Submitted by: | E31: Noted by: | J31: Coordinating Office:
J32: C. Carp:
J33: Ornamental Fish:
B34: GAYMELO Y. LOPEZ | E34: MARIO N. RUINATA, Ph. D. | J34: Catfish:
B35: AQUA II/OIC- Center Chief | E35: Research, Development & Extension Coordinating Office | J35: Freshwater Prawn:
J36: Total area (sq.m)
J37: Freshwater:
J38: Brackishwater:

Sheet September 2020
A1: FORMAT LIST OF ACTUAL BENEFICIARIES
B2: September, 2020
J3: Total No. Of Beneficiaries:
J4: Male:
J5: Female:
A6: a. Individuals | J6: Others:(S.C./PWD)
F7: Types of Goods/Services Received | J7: DATE OF IMPLEMENTATION
A8: NAME OF BENEFICIARIES | C8: GENDER | D8: BARANGAY | E8: MUNICIPALITY | F8: Contact No./Email | H8: QUANTITY | I8: COST('000)
F9: Address(if any) | G9: Type/Species | H9: RECEIVED | J9: TYPE | K9: SATISFIED/
H10: (Unit/kg/pcs.) | K10: NOT SATISFIED
A11: DATE
A12: 1 | B12: Simplicio Balonga Jr. | C12: Male | D12: Cabiguhan | E12: Trinidad | G12: Excel | H12: 15000 | I12: 3000 | J12: pond | K12: satisfied | M12: 1500
A13: 1 | B13: Francisco Fernandez | C13: Male | D13: Hagbuyo | E13: San Miguel | G13: Excel | H13: 1000 | I13: 200 | J13: pond | K13: satisfied | M13: 400
A14: 1 | B14: Daniel Sabior | C14: Male | D14: La Libertad | E14: Carmen | G14: Excel | H14: 500 | I14: dispersal | J14: pond | K14: satisfied | M14: 228
A15: 1 | B15: Daniel Sabior | C15: Male | D15: La Libertad | E15: Carmen | G15: Excel | H15: 1000 | I15: 200 | J15: pond | K15: satisfied
A16: 1 | B16: Analyn Gamella | C16: Female | D16: Canmano | E16: Sagbayan | G16: Excel | H16: 500 | I16: 100 | J16: pond | K16: satisfied | M16: 150
A17: 1 | B17: Rosalita Buaya | C17: Female | D17: Canmano | E17: Sagbayan | G17: Excel | H17: 500 | I17: 100 | J17: pond | K17: satisfied | M17: 150
A18: 1 | B18: Eduardo Yagonia | C18: Male | D18: Canmano | E18: Sagbayan | G18: Excel | H18: 500 | I18: 100 | J18: pond | K18: satisfied | M18: 150
A19: 1 | B19: Adelo Legaspi | C19: Male | D19: Nueva Vida Sur | E19: Carmen | G19: Excel | H19: 1000 | I19: 200 | J19: pond | K19: satisfied | M19: 200
A20: 1 | B20: Deuel Puracan | C20: Male | D20: Cabiguhan | E20: Trinidad | G20: Excel | H20: 25000 | I20: 5000 | J20: pond | K20: satisfied | M20: 5000
A21: 1 | B21: Nelson Tonido | C21: Male | D21: Bugang | E21: San Miguel | G21: Excel | H21: 20000 | I21: 4000 | J21: pond | K21: satisfied | M21: 10000
A22: 1 | B22: Mario Alvarez | C22: Male | D22: Bugang | E22: San Miguel | G22: Excel | H22: 5500 | I22: 1100 | J22: pond | K22: satisfied | M22: 2500
A23: 1 | B23: Roger Tinampay | C23: Male | D23: San Miguel | E23: Dagohoy | G23: Excel | H23: 12500 | I23: 2500 | J23: pond | K23: satisfied | M23: 3000
A24: 1 | B24: Roger Tinampay | C24: Male | D24: San Miguel | E24: Dagohoy | G24: C. carp | H24: 500 | I24: 300 | J24: pond | K24: satisfied
A25: 1 | B25: Joseph Escalante | C25: Male | D25: Poblacion | E25: Pilar | G25: Excel | H25: 500 | I25: dispersal | J25: pond | K25: satisfied | M25: 100
A26: 2 | B26: Crispin Lumantas | C26: Male | D26: Calingaan | E26: Sevilla | G26: Excel | H26: 4000 | I26: 1600 | J26: pond | K26: satisfied
A27: 2 | B27: Crispin Lumantas | C27: Male | D27: Calingaan | E27: Sevilla | G27: Excel | H27: 1000 | I27: 300 | J27: pond | K27: satisfied
A28: 2 | B28: Mark Joseph Gara | C28: Male | D28: Katipunan | E28: Alicia | G28: Excel | H28: 350 | I28: 105 | J28: pond | K28: satisfied | M28: 100
A29: 2 | B29: Jaime Quinio | C29: Male | D29: San Pascual | E29: Ubay | G29: Excel | H29: 1000 | I29: 300 | J29: pond | K29: satisfied | M29: 330
A30: 2 | B30: Maximo Assister | C30: Male | D30: Alegria | E30: Carmen | G30: Excel | H30: 300 | I30: 90 | J30: pond | K30: satisfied | M30: 50
A31: 2 | B31: Ares dela Torre | C31: Male | D31: Libertad | E31: Tubigon | G31: Excel | H31: 2000 | I31: 600 | J31: pond | K31: satisfied | M31: 600
A32: 2 | B32: Manuel Gutas | C32: Male | D32: Katipunan | E32: Carmen | G32: Excel | H32: 4000 | I32: 800 | J32: pond | K32: satisfied | M32: 700
A33: 2 | B33: Marvin Lubiano | C33: Male | D33: Libertad | E33: Tubigon | G33: Excel | H33: 100 | I33: 30 | J33: pond | K33: satisfied | M33: 30
A34: 2 | B34: Romeo Lenteria | C34: Male | D34: Bagumbayan | E34: Pilar | G34: Excel | H34: 500 | I34: 100 | J34: pond | K34: satisfied | M34: 100
